Workbook

Sheet Template Audit
A1: Priority Tier | B1: Category | C1: Asset/Template Name | D1: Description | E1: Format | F1: Status | G1: Dependencies | H1: Deadline | I1: Owner | J1: Notes
A2: 1 | B2: Logo System | C2: Primary Logo Files (SVG, PNG, EPS, AI) | D2: Full-color, single-color, reversed, all colorway variations | E2: SVG/PNG/EPS/AI | F2: Not Started | H2: 2026-03-31 | I2: Chris | J2: All formats needed for different applications
A3: 1 | B3: Logo System | C3: Secondary/Alternate Mark | D3: Secondary mark variations for constrained spaces | E3: SVG/PNG/EPS/AI | F3: Not Started | G3: Primary Logo Files | H3: 2026-03-31 | I3: Chris
A4: 1 | B4: Logo System | C4: Sub-Brand Lockup Templates | D4: Lockup templates for: Reboot, Energy Summit, Dynamist, FAI Labs, Policy Hackers, Schoolahoop, BIPBounty, Project Nickel | E4: AI/Figma | F4: Not Started | G4: Primary Logo Files | H4: 2026-05-31 | I4: Chris | J4: 8 sub-brand lockups needed
A5: 1 | B5: Logo System | C5: Logo Usage Guide Page | D5: Page for brand book showing logo specifications, clearspace, sizing, dos/donts | E5: PDF/InDesign | F5: Not Started | G5: Primary Logo Files | H5: 2026-04-30 | I5: Chris
A6: 1 | B6: Logo System | C6: Favicon & App Icon Set | D6: 16x16, 32x32, 64x64, 128x128, 180x180 (iOS), 192x192 (Android) | E6: PNG/ICO | F6: Not Started | G6: Primary Logo Files | H6: 2026-05-31 | I6: Chris
A7: 1 | B7: Logo System | C7: Watermark Versions | D7: Semi-transparent logo for background/document watermarking | E7: PNG/PDF | F7: Not Started | G7: Primary Logo Files | H7: 2026-05-31 | I7: Chris
A8: 1 | B8: Color System | C8: Color Specification Sheet | D8: HEX, RGB, CMYK, Pantone values for primary and secondary palettes | E8: XLSX/PDF | F8: Not Started | H8: 2026-03-31 | I8: Chris | J8: Include accessibility notes
A9: 1 | B9: Color System | C9: Color Palette Files (ASE, CLR) | D9: Adobe Swatch Exchange and macOS/Windows color palette files | E9: ASE/CLR | F9: Not Started | G9: Color Specification Sheet | H9: 2026-04-15 | I9: Chris
A10: 1 | B10: Color System | C10: Accessibility Contrast Ratio Documentation | D10: WCAG AA/AAA compliance chart for all color combinations | E10: PDF/XLSX | F10: Not Started | G10: Color Specification Sheet | H10: 2026-04-30 | I10: Chris
A11: 1 | B11: Color System | C11: Sub-Brand Color Extensions | D11: Color palettes for each sub-brand within system | E11: ASE/CLR/PDF | F11: Not Started | G11: Color Specification Sheet | H11: 2026-05-31 | I11: Chris
A12: 1 | B12: Typography | C12: Typeface License Documentation | D12: Licensed typeface details, usage restrictions, web font rights | E12: PDF | F12: Not Started | H12: 2026-03-15 | I12: Chris
A13: 1 | B13: Typography | C13: Type Specimen Sheet | D13: Full alphabet, numerals, punctuation in all weights/styles | E13: PDF/InDesign | F13: Not Started | G13: Typeface License Documentation | H13: 2026-03-31 | I13: Chris
A14: 1 | B14: Typography | C14: Web Font Files | D14: WOFF2 and fallback formats for web implementation | E14: WOFF2/WOFF/TTF | F14: Not Started | G14: Typeface License Documentation | H14: 2026-04-15 | I14: Chris
A15: 1 | B15: Typography | C15: Typography Hierarchy Reference Card | D15: Headline, subheading, body, caption specs with line-height and letter-spacing | E15: PDF/XLSX | F15: Not Started | G15: Type Specimen Sheet | H15: 2026-03-31 | I15: Chris
A16: 1 | B16: Voice & Tone | C16: Brand Voice Guidelines | D16: Voice characteristics, tone variations (professional, approachable, authoritative, etc.) | E16: PDF/DOCX | F16: Not Started | H16: 2026-04-30 | I16: Chris
A17: 1 | B17: Voice & Tone | C17: Boilerplate Copy Library | D17: About paragraphs (50, 100, 150 words), mission statement, program descriptions | E17: DOCX/PDF | F17: Not Started | G17: Brand Voice Guidelines | H17: 2026-04-30 | I17: Chris | J17: Include variations for each sub-brand
A18: 1 | B18: Voice & Tone | C18: Terminology Glossary | D18: FAI-specific terms, acronyms, preferred usage (e.g., AI, policy, tech) | E18: XLSX/PDF | F18: Not Started | G18: Brand Voice Guidelines | H18: 2026-04-30 | I18: Chris
A19: 1 | B19: Voice & Tone | C19: Email Signature Standard | D19: HTML and plain-text signature templates with logo, contact info | E19: HTML/DOCX | F19: Not Started | G19: Typography;Logo System | H19: 2026-04-15 | I19: Chris
A20: 2 | B20: Publications | C20: Web-Native Policy Paper Template | D20: HTML/CSS responsive template for publishing policy papers on website | E20: HTML/CSS | F20: Not Started | G20: Typography;Color System | H20: 2026-03-31 | I20: Chris | J20: High priority - March 31 deadline
A21: 2 | B21: Publications | C21: Print Policy Brief Template | D21: 2-4 page InDesign template for policy briefs | E21: INDD/PDF | F21: Not Started | G21: Typography;Color System;Logo System | H21: 2026-04-30 | I21: Chris
A22: 2 | B22: Publications | C22: Print Research Report Template | D22: Multi-page InDesign template (8-20 pages typical) | E22: INDD/PDF | F22: Not Started | G22: Typography;Color System;Logo System | H22: 2026-05-31 | I22: Chris
A23: 2 | B23: Publications | C23: Print Booklet/Program Template | D23: InDesign template for event programs and booklets (Copyright Symposium, summits) | E23: INDD/PDF | F23: Existing/Needs Update | G23: Typography;Logo System | H23: 2026-02-27 | I23: Chris | J23: URGENT: Copyright Symposium Feb 27
A24: 2 | B24: Publications | C24: Blog Post Style Guide | D24: Formatting, structure, and design specs for Sanity CMS blog posts | E24: PDF/DOCX | F24: Not Started | G24: Typography;Color System | H24: 2026-05-31 | I24: Chris
A25: 2 | B25: Publications | C25: Book/Publication Cover Template | D25: InDesign template for external and internal publications | E25: INDD/PDF | F25: Not Started | G25: Typography;Color System;Logo System | H25: 2026-06-15 | I25: Chris
A26: 2 | B26: Presentations | C26: Master FAI Deck Template | D26: PPTX and Keynote master slide templates with layouts | E26: PPTX/KEYNOTE | F26: Existing/Needs Update | G26: Typography;Color System;Logo System | H26: 2026-02-27 | I26: Chris | J26: URGENT: Update FAI deck Feb 27
A27: 2 | B27: Presentations | C27: Internal Meeting Deck Template | D27: Simplified template for internal team presentations | E27: PPTX/KEYNOTE | F27: Not Started | G27: Master FAI Deck Template | H27: 2026-04-30 | I27: Chris
A28: 2 | B28: Presentations | C28: Webinar/Virtual Event Slide Template | D28: Template optimized for screen sharing and virtual delivery | E28: PPTX/KEYNOTE | F28: Not Started | G28: Master FAI Deck Template | H28: 2026-05-31 | I28: Chris
A29: 2 | B29: Presentations | C29: Speaker One-Sheet/Bio Template | D29: Half-page or one-page template for speaker bios with photo placement | E29: DOCX/PDF | F29: Not Started | G29: Typography;Logo System | H29: 2026-04-15 | I29: Chris
A30: 2 | B30: Social Media | C30: X/Twitter Post Templates | D30: Quote card, announcement, event promo, stat/data templates (Figma or PPTX) | E30: FIGMA/PPTX | F30: Not Started | G30: Color System;Typography;Logo System | H30: 2026-05-31 | I30: Chris | J30: 4 template variations
A31: 2 | B31: Social Media | C31: LinkedIn Post Templates | D31: Article share, announcement, event templates (image specs) | E31: FIGMA/PPTX | F31: Not Started | G31: Color System;Typography;Logo System | H31: 2026-05-31 | I31: Chris
A32: 2 | B32: Social Media | C32: YouTube Thumbnail Template | D32: 1280x720px template with text, logo, graphics specs | E32: FIGMA/PPTX | F32: Not Started | G32: Color System;Typography;Logo System | H32: 2026-05-31 | I32: Chris
A33: 2 | B33: Social Media | C33: YouTube Channel Art | D33: 2560x1440px banner for channel header | E33: FIGMA/PPTX | F33: Not Started | G33: Logo System;Color System | H33: 2026-05-31 | I33: Chris
A34: 2 | B34: Social Media | C34: Instagram Templates | D34: 1080x1350 (feed), 1080x1920 (story), carousel specs if applicable | E34: FIGMA/PPTX | F34: Not Started | G34: Color System;Typography;Logo System | H34: 2026-05-31 | I34: Chris
A35: 2 | B35: Social Media | C35: Social Media Avatar & Profile Photo Specs | D35: Size, format, and brand guidelines for profile pictures | E35: PDF/FIGMA | F35: Not Started | G35: Logo System | H35: 2026-04-15 | I35: Chris
A36: 2 | B36: Social Media | C36: Podcast Cover Art Template (The Dynamist) | D36: 3000x3000px Apple Podcasts and Spotify compliant template | E36: FIGMA/PPTX | F36: Not Started | G36: Logo System;Color System | H36: 2026-05-31 | I36: Chris | J36: The Dynamist sub-brand
A37: 2 | B37: Email / Newsletter | C37: The SCIF Newsletter Template | D37: HTML email template with responsive design (150, 600, 800px widths) | E37: HTML | F37: Not Started | G37: Typography;Color System;Logo System | H37: 2026-04-30 | I37: Chris | J37: SCIF is weekly newsletter
A38: 2 | B38: Email / Newsletter | C38: Event Invitation Email Template | D38: HTML email for event RSVPs with CTA buttons | E38: HTML | F38: Not Started | G38: Typography;Logo System;Color System | H38: 2026-04-30 | I38: Chris
A39: 2 | B39: Email / Newsletter | C39: Fundraising/Donor Email Template | D39: HTML template for donor appeals and campaigns | E39: HTML | F39: Not Started | G39: Typography;Logo System;Color System | H39: 2026-05-31 | I39: Chris
A40: 2 | B40: Email / Newsletter | C40: Internal Announcement Email Template | D40: HTML template for team announcements | E40: HTML | F40: Not Started | G40: Typography;Logo System;Color System | H40: 2026-04-30 | I40: Chris
...

Sheet Summary Dashboard
A1: FAI Brand Refresh - Template Audit Summary
A3: SUMMARY BY TIER
A4: Tier | B4: Total Items | C4: Not Started | D4: In Progress | E4: Existing/Needs Update | F4: Complete
A5: Tier 1 (Foundation) | B5: =COUNTIF('Template Audit'!A:A,1) -> 18 | C5: =COUNTIFS('Template Audit'!A:A,1,'Template Audit'!F:F,"Not Started") -> 18 | D5: =COUNTIFS('Template Audit'!A:A,1,'Template Audit'!F:F,"In Progress") -> 0 | E5: =COUNTIFS('Template Audit'!A:A,1,'Template Audit'!F:F,"Existing/Needs Update") -> 0 | F5: =COUNTIFS('Template Audit'!A:A,1,'Template Audit'!F:F,"Complete") -> 0
A6: Tier 2 (Core Templates) | B6: =COUNTIF('Template Audit'!A:A,2) -> 36 | C6: =COUNTIFS('Template Audit'!A:A,2,'Template Audit'!F:F,"Not Started") -> 34 | D6: =COUNTIFS('Template Audit'!A:A,2,'Template Audit'!F:F,"In Progress") -> 0 | E6: =COUNTIFS('Template Audit'!A:A,2,'Template Audit'!F:F,"Existing/Needs Update") -> 2 | F6: =COUNTIFS('Template Audit'!A:A,2,'Template Audit'!F:F,"Complete") -> 0
A7: Tier 3 (Extended Applications) | B7: =COUNTIF('Template Audit'!A:A,3) -> 35 | C7: =COUNTIFS('Template Audit'!A:A,3,'Template Audit'!F:F,"Not Started") -> 35 | D7: =COUNTIFS('Template Audit'!A:A,3,'Template Audit'!F:F,"In Progress") -> 0 | E7: =COUNTIFS('Template Audit'!A:A,3,'Template Audit'!F:F,"Existing/Needs Update") -> 0 | F7: =COUNTIFS('Template Audit'!A:A,3,'Template Audit'!F:F,"Complete") -> 0
A8: TOTAL | B8: =SUM(B5:B7) -> 89 | C8: =SUM(C5:C7) -> 87 | D8: =SUM(D5:D7) -> 0 | E8: =SUM(E5:E7) -> 2 | F8: =SUM(F5:F7) -> 0
A10: SUMMARY BY CATEGORY
A11: Category | B11: Total Items | C11: Complete | D11: In Progress | E11: Existing/Needs Update | F11: Not Started
A12: Logo System | B12: =COUNTIF('Template Audit'!B:B,"Logo System") -> 6 | C12: =COUNTIFS('Template Audit'!B:B,"Logo System",'Template Audit'!F:F,"Complete") -> 0 | D12: =COUNTIFS('Template Audit'!B:B,"Logo System",'Template Audit'!F:F,"In Progress") -> 0 | E12: =COUNTIFS('Template Audit'!B:B,"Logo System",'Template Audit'!F:F,"Existing/Needs Update") -> 0 | F12: =COUNTIFS('Template Audit'!B:B,"Logo System",'Template Audit'!F:F,"Not Started") -> 6
A13: Color System | B13: =COUNTIF('Template Audit'!B:B,"Color System") -> 4 | C13: =COUNTIFS('Template Audit'!B:B,"Color System",'Template Audit'!F:F,"Complete") -> 0 | D13: =COUNTIFS('Template Audit'!B:B,"Color System",'Template Audit'!F:F,"In Progress") -> 0 | E13: =COUNTIFS('Template Audit'!B:B,"Color System",'Template Audit'!F:F,"Existing/Needs Update") -> 0 | F13: =COUNTIFS('Template Audit'!B:B,"Color System",'Template Audit'!F:F,"Not Started") -> 4
A14: Typography | B14: =COUNTIF('Template Audit'!B:B,"Typography") -> 4 | C14: =COUNTIFS('Template Audit'!B:B,"Typography",'Template Audit'!F:F,"Complete") -> 0 | D14: =COUNTIFS('Template Audit'!B:B,"Typography",'Template Audit'!F:F,"In Progress") -> 0 | E14: =COUNTIFS('Template Audit'!B:B,"Typography",'Template Audit'!F:F,"Existing/Needs Update") -> 0 | F14: =COUNTIFS('Template Audit'!B:B,"Typography",'Template Audit'!F:F,"Not Started") -> 4
A15: Voice & Tone | B15: =COUNTIF('Template Audit'!B:B,"Voice & Tone") -> 4 | C15: =COUNTIFS('Template Audit'!B:B,"Voice & Tone",'Template Audit'!F:F,"Complete") -> 0 | D15: =COUNTIFS('Template Audit'!B:B,"Voice & Tone",'Template Audit'!F:F,"In Progress") -> 0 | E15: =COUNTIFS('Template Audit'!B:B,"Voice & Tone",'Template Audit'!F:F,"Existing/Needs Update") -> 0 | F15: =COUNTIFS('Template Audit'!B:B,"Voice & Tone",'Template Audit'!F:F,"Not Started") -> 4
A16: Publications | B16: =COUNTIF('Template Audit'!B:B,"Publications") -> 6 | C16: =COUNTIFS('Template Audit'!B:B,"Publications",'Template Audit'!F:F,"Complete") -> 0 | D16: =COUNTIFS('Template Audit'!B:B,"Publications",'Template Audit'!F:F,"In Progress") -> 0 | E16: =COUNTIFS('Template Audit'!B:B,"Publications",'Template Audit'!F:F,"Existing/Needs Update") -> 1 | F16: =COUNTIFS('Template Audit'!B:B,"Publications",'Template Audit'!F:F,"Not Started") -> 5
A17: Presentations | B17: =COUNTIF('Template Audit'!B:B,"Presentations") -> 4 | C17: =COUNTIFS('Template Audit'!B:B,"Presentations",'Template Audit'!F:F,"Complete") -> 0 | D17: =COUNTIFS('Template Audit'!B:B,"Presentations",'Template Audit'!F:F,"In Progress") -> 0 | E17: =COUNTIFS('Template Audit'!B:B,"Presentations",'Template Audit'!F:F,"Existing/Needs Update") -> 1 | F17: =COUNTIFS('Template Audit'!B:B,"Presentations",'Template Audit'!F:F,"Not Started") -> 3
A18: Social Media | B18: =COUNTIF('Template Audit'!B:B,"Social Media") -> 7 | C18: =COUNTIFS('Template Audit'!B:B,"Social Media",'Template Audit'!F:F,"Complete") -> 0 | D18: =COUNTIFS('Template Audit'!B:B,"Social Media",'Template Audit'!F:F,"In Progress") -> 0 | E18: =COUNTIFS('Template Audit'!B:B,"Social Media",'Template Audit'!F:F,"Existing/Needs Update") -> 0 | F18: =COUNTIFS('Template Audit'!B:B,"Social Media",'Template Audit'!F:F,"Not Started") -> 7
A19: Email / Newsletter | B19: =COUNTIF('Template Audit'!B:B,"Email / Newsletter") -> 5 | C19: =COUNTIFS('Template Audit'!B:B,"Email / Newsletter",'Template Audit'!F:F,"Complete") -> 0 | D19: =COUNTIFS('Template Audit'!B:B,"Email / Newsletter",'Template Audit'!F:F,"In Progress") -> 0 | E19: =COUNTIFS('Template Audit'!B:B,"Email / Newsletter",'Template Audit'!F:F,"Existing/Needs Update") -> 0 | F19: =COUNTIFS('Template Audit'!B:B,"Email / Newsletter",'Template Audit'!F:F,"Not Started") -> 5
A20: Events | B20: =COUNTIF('Template Audit'!B:B,"Events") -> 9 | C20: =COUNTIFS('Template Audit'!B:B,"Events",'Template Audit'!F:F,"Complete") -> 0 | D20: =COUNTIFS('Template Audit'!B:B,"Events",'Template Audit'!F:F,"In Progress") -> 0 | E20: =COUNTIFS('Template Audit'!B:B,"Events",'Template Audit'!F:F,"Existing/Needs Update") -> 0 | F20: =COUNTIFS('Template Audit'!B:B,"Events",'Template Audit'!F:F,"Not Started") -> 9
A21: Stationery | B21: =COUNTIF('Template Audit'!B:B,"Stationery") -> 5 | C21: =COUNTIFS('Template Audit'!B:B,"Stationery",'Template Audit'!F:F,"Complete") -> 0 | D21: =COUNTIFS('Template Audit'!B:B,"Stationery",'Template Audit'!F:F,"In Progress") -> 0 | E21: =COUNTIFS('Template Audit'!B:B,"Stationery",'Template Audit'!F:F,"Existing/Needs Update") -> 0 | F21: =COUNTIFS('Template Audit'!B:B,"Stationery",'Template Audit'!F:F,"Not Started") -> 5
A22: Sub-Brand Guidelines | B22: =COUNTIF('Template Audit'!B:B,"Sub-Brand Guidelines") -> 6 | C22: =COUNTIFS('Template Audit'!B:B,"Sub-Brand Guidelines",'Template Audit'!F:F,"Complete") -> 0 | D22: =COUNTIFS('Template Audit'!B:B,"Sub-Brand Guidelines",'Template Audit'!F:F,"In Progress") -> 0 | E22: =COUNTIFS('Template Audit'!B:B,"Sub-Brand Guidelines",'Template Audit'!F:F,"Existing/Needs Update") -> 0 | F22: =COUNTIFS('Template Audit'!B:B,"Sub-Brand Guidelines",'Template Audit'!F:F,"Not Started") -> 6
A23: Donor/Development Materials | B23: =COUNTIF('Template Audit'!B:B,"Donor/Development Materials") -> 6 | C23: =COUNTIFS('Template Audit'!B:B,"Donor/Development Materials",'Template Audit'!F:F,"Complete") -> 0 | D23: =COUNTIFS('Template Audit'!B:B,"Donor/Development Materials",'Template Audit'!F:F,"In Progress") -> 0 | E23: =COUNTIFS('Template Audit'!B:B,"Donor/Development Materials",'Template Audit'!F:F,"Existing/Needs Update") -> 0 | F23: =COUNTIFS('Template Audit'!B:B,"Donor/Development Materials",'Template Audit'!F:F,"Not Started") -> 6
A24: Swag & Merchandise | B24: =COUNTIF('Template Audit'!B:B,"Swag & Merchandise") -> 7 | C24: =COUNTIFS('Template Audit'!B:B,"Swag & Merchandise",'Template Audit'!F:F,"Complete") -> 0 | D24: =COUNTIFS('Template Audit'!B:B,"Swag & Merchandise",'Template Audit'!F:F,"In Progress") -> 0 | E24: =COUNTIFS('Template Audit'!B:B,"Swag & Merchandise",'Template Audit'!F:F,"Existing/Needs Update") -> 0 | F24: =COUNTIFS('Template Audit'!B:B,"Swag & Merchandise",'Template Audit'!F:F,"Not Started") -> 7
A25: Digital/Web | B25: =COUNTIF('Template Audit'!B:B,"Digital/Web") -> 6 | C25: =COUNTIFS('Template Audit'!B:B,"Digital/Web",'Template Audit'!F:F,"Complete") -> 0 | D25: =COUNTIFS('Template Audit'!B:B,"Digital/Web",'Template Audit'!F:F,"In Progress") -> 0 | E25: =COUNTIFS('Template Audit'!B:B,"Digital/Web",'Template Audit'!F:F,"Existing/Needs Update") -> 0 | F25: =COUNTIFS('Template Audit'!B:B,"Digital/Web",'Template Audit'!F:F,"Not Started") -> 6
A26: Video/Motion | B26: =COUNTIF('Template Audit'!B:B,"Video/Motion") -> 5 | C26: =COUNTIFS('Template Audit'!B:B,"Video/Motion",'Template Audit'!F:F,"Complete") -> 0 | D26: =COUNTIFS('Template Audit'!B:B,"Video/Motion",'Template Audit'!F:F,"In Progress") -> 0 | E26: =COUNTIFS('Template Audit'!B:B,"Video/Motion",'Template Audit'!F:F,"Existing/Needs Update") -> 0 | F26: =COUNTIFS('Template Audit'!B:B,"Video/Motion",'Template Audit'!F:F,"Not Started") -> 5
A27: Governance | B27: =COUNTIF('Template Audit'!B:B,"Governance") -> 5 | C27: =COUNTIFS('Template Audit'!B:B,"Governance",'Template Audit'!F:F,"Complete") -> 0 | D27: =COUNTIFS('Template Audit'!B:B,"Governance",'Template Audit'!F:F,"In Progress") -> 0 | E27: =COUNTIFS('Template Audit'!B:B,"Governance",'Template Audit'!F:F,"Existing/Needs Update") -> 0 | F27: =COUNTIFS('Template Audit'!B:B,"Governance",'Template Audit'!F:F,"Not Started") -> 5

Sheet Timeline View
A1: Deadline | B1: Tier | C1: Category | D1: Asset Name | E1: Status | F1: Dependencies
A2: 2026-02-27 | B2: 2 | C2: Publications | D2: Print Booklet/Program Template | E2: Existing/Needs Update | F2: Typography;Logo System
A3: 2026-02-27 | B3: 2 | C3: Presentations | D3: Master FAI Deck Template | E3: Existing/Needs Update | F3: Typography;Color System;Logo System
A4: 2026-03-15 | B4: 1 | C4: Typography | D4: Typeface License Documentation | E4: Not Started
A5: 2026-03-31 | B5: 1 | C5: Logo System | D5: Primary Logo Files (SVG, PNG, EPS, AI) | E5: Not Started
A6: 2026-03-31 | B6: 1 | C6: Logo System | D6: Secondary/Alternate Mark | E6: Not Started | F6: Primary Logo Files
A7: 2026-03-31 | B7: 1 | C7: Color System | D7: Color Specification Sheet | E7: Not Started
A8: 2026-03-31 | B8: 1 | C8: Typography | D8: Type Specimen Sheet | E8: Not Started | F8: Typeface License Documentation
A9: 2026-03-31 | B9: 1 | C9: Typography | D9: Typography Hierarchy Reference Card | E9: Not Started | F9: Type Specimen Sheet
A10: 2026-03-31 | B10: 2 | C10: Publications | D10: Web-Native Policy Paper Template | E10: Not Started | F10: Typography;Color System
A11: 2026-04-15 | B11: 1 | C11: Color System | D11: Color Palette Files (ASE, CLR) | E11: Not Started | F11: Color Specification Sheet
A12: 2026-04-15 | B12: 1 | C12: Typography | D12: Web Font Files | E12: Not Started | F12: Typeface License Documentation
A13: 2026-04-15 | B13: 1 | C13: Voice & Tone | D13: Email Signature Standard | E13: Not Started | F13: Typography;Logo System
A14: 2026-04-15 | B14: 2 | C14: Presentations | D14: Speaker One-Sheet/Bio Template | E14: Not Started | F14: Typography;Logo System
A15: 2026-04-15 | B15: 2 | C15: Social Media | D15: Social Media Avatar & Profile Photo Specs | E15: Not Started | F15: Logo System
A16: 2026-04-15 | B16: 2 | C16: Email / Newsletter | D16: Email Signature Template | E16: Not Started | F16: Typography;Logo System
A17: 2026-04-30 | B17: 1 | C17: Logo System | D17: Logo Usage Guide Page | E17: Not Started | F17: Primary Logo Files
A18: 2026-04-30 | B18: 1 | C18: Color System | D18: Accessibility Contrast Ratio Documentation | E18: Not Started | F18: Color Specification Sheet
A19: 2026-04-30 | B19: 1 | C19: Voice & Tone | D19: Brand Voice Guidelines | E19: Not Started
A20: 2026-04-30 | B20: 1 | C20: Voice & Tone | D20: Boilerplate Copy Library | E20: Not Started | F20: Brand Voice Guidelines
A21: 2026-04-30 | B21: 1 | C21: Voice & Tone | D21: Terminology Glossary | E21: Not Started | F21: Brand Voice Guidelines
A22: 2026-04-30 | B22: 2 | C22: Publications | D22: Print Policy Brief Template | E22: Not Started | F22: Typography;Color System;Logo System
A23: 2026-04-30 | B23: 2 | C23: Presentations | D23: Internal Meeting Deck Template | E23: Not Started | F23: Master FAI Deck Template
A24: 2026-04-30 | B24: 2 | C24: Email / Newsletter | D24: The SCIF Newsletter Template | E24: Not Started | F24: Typography;Color System;Logo System
A25: 2026-04-30 | B25: 2 | C25: Email / Newsletter | D25: Event Invitation Email Template | E25: Not Started | F25: Typography;Logo System;Color System
A26: 2026-04-30 | B26: 2 | C26: Email / Newsletter | D26: Internal Announcement Email Template | E26: Not Started | F26: Typography;Logo System;Color System
A27: 2026-04-30 | B27: 2 | C27: Events | D27: Event Program/Booklet Template | E27: Not Started | F27: Typography;Logo System;Event Branding Toolkit
A28: 2026-04-30 | B28: 2 | C28: Events | D28: Name Badge Template | E28: Not Started | F28: Typography;Logo System
A29: 2026-04-30 | B29: 2 | C29: Events | D29: Event Invitation (Digital - Luma) | E29: Not Started | F29: Typography;Logo System;Color System
A30: 2026-04-30 | B30: 2 | C30: Events | D30: Event Invitation (Print) | E30: Not Started | F30: Typography;Logo System;Color System
A31: 2026-04-30 | B31: 2 | C31: Events | D31: Table Tent/Place Card Template | E31: Not Started | F31: Typography;Logo System
... A59: 2026-06-30 | B59: 3 | C59: Governance | D59: New Sub-Brand Proposal Template | E59: Not Started | F59: Brand Voice Guidelines
A60: 2026-06-30 | B60: 3 | C60: Governance | D60: Asset Request Form | E60: Not Started
A61: 2026-07-31 | B61: 3 | C61: Sub-Brand Guidelines | D61: Reboot Conference Identity Package | E61: Not Started | F61: Logo System;Color System;Typography;Sub-Brand Lockup Templates
A62: 2026-07-31 | B62: 3 | C62: Sub-Brand Guidelines | D62: Energy Imperatives Summit Identity Package | E62: Not Started | F62: Logo System;Color System;Typography;Sub-Brand Lockup Templates
A63: 2026-07-31 | B63: 3 | C63: Sub-Brand Guidelines | D63: FAI Labs Identity Package | E63: Not Started | F63: Logo System;Color System;Typography;Sub-Brand Lockup Templates
A64: 2026-07-31 | B64: 3 | C64: Sub-Brand Guidelines | D64: Policy Hackers Identity Package | E64: Not Started | F64: Logo System;Color System;Typography;Sub-Brand Lockup Templates
A65: 2026-07-31 | B65: 3 | C65: Donor/Development Materials | D65: Donor One-Pager Template | E65: Not Started | F65: Typography;Logo System
A66: 2026-07-31 | B66: 3 | C66: Donor/Development Materials | D66: Grant Proposal Cover Template | E66: Not Started | F66: Typography;Logo System
A67: 2026-07-31 | B67: 3 | C67: Digital/Web | D67: Website Redesign Brief | E67: Not Started | F67: Logo System;Color System;Typography
...
